Workbook

Sheet OriginalData
A1: record number | B1: datetime | C1: season | D1: holiday | E1: weather | F1: temp | G1: humidity | H1: windspeed | I1: casual | J1: registered | K1: all_users
A2: 1 | B2: 40922.25 | C2: 1 | D2: 0 | E2: 1 | F2: -2 | G2: 50 | H2: 0 | I2: 0 | J2: 5 | K2: 5
A3: 2 | B3: 40748.167 | C3: 3 | D3: 0 | E3: 1 | F3: 30 | G3: 66 | H3: 7.0015 | I3: 1 | J3: 5 | K3: 6
A4: 3 | B4: 40825.292 | C4: 4 | D4: 0 | E4: 1 | F4: 13 | G4: 86 | H4: 0 | I4: 18 | J4: 26 | K4: 44
A5: 4 | B5: 41255.875 | C5: 4 | D5: 0 | E5: 2 | F5: 6 | G5: 52 | H5: 16.9979 | I5: 16 | J5: 186 | K5: 202
A6: 5 | B6: 40716.542 | C6: 3 | D6: 0 | E6: 2 | F6: 32 | G6: 56 | H6: 16.9979 | I6: 33 | J6: 112 | K6: 145
A7: 6 | B7: 40779.75 | C7: 3 | D7: 0 | E7: 1 | F7: 28 | G7: 55 | H7: 19.9995 | I7: 102 | J7: 518 | K7: 620
A8: 7 | B8: 40909.833 | C8: 1 | D8: 0 | E8: 2 | F8: 13 | G8: 62 | H8: 19.9995 | I8: 25 | J8: 58 | K8: 83
A9: 8 | B9: 40640.625 | C9: 2 | D9: 0 | E9: 1 | F9: 21 | G9: 38 | H9: 7.0015 | I9: 27 | J9: 133 | K9: 160
A10: 9 | B10: 41177.75 | C10: 4 | D10: 0 | E10: 1 | F10: 23 | G10: 41 | H10: 15.0013 | I10: 64 | J10: 758 | K10: 822
A11: 10 | B11: 41122.167 | C11: 3 | D11: 0 | E11: 2 | F11: 23 | G11: 78 | H11: 8.9981 | I11: 1 | J11: 3 | K11: 4
A12: 11 | B12: 41117.75 | C12: 3 | D12: 0 | E12: 1 | F12: 32 | G12: 46 | H12: 11.0014 | I12: 100 | J12: 522 | K12: 622
A13: 12 | B13: 41054.167 | C13: 2 | D13: 0 | E13: 2 | F13: 22 | G13: 88 | H13: 0 | I13: 3 | J13: 5 | K13: 8
... A17514: 17513 | B17514: 40755.792 | C17514: 3 | D17514: 0 | E17514: 1 | F17514: 31 | G17514: 55 | H17514: 22.0028 | I17514: 87 | J17514: 187 | K17514: 274

Sheet Processed Data
A1: record number | B1: datetime | C1: season | D1: holiday | E1: weather | F1: temp | G1: humidity | H1: windspeed | I1: casual | J1: registered | K1: all_users | L1: Year | M1: Month | N1: Day of Week | O1: Hour | P1: Weekend | Q1: Weekend Number | R1: Mist | S1: Percipitation | T1: Spring | U1: Summer | V1: Fall | W1: Year 2012 | X1: Temp (F)
A2: 11325 | B2: 41105.792 | C2: 3 | D2: 0 | E2: 1 | F2: 27 | G2: 84 | H2: 15.0013 | I2: 109 | J2: 203 | K2: 312 | L2: =YEAR(B2) -> 2012 | M2: =MONTH(B2) -> 7 | N2: =WEEKDAY(B2,2) -> 7 | O2: =HOUR(B2) -> 19 | P2: =IF(N2>5,1,0) -> 1 | Q2: =WEEKNUM(B2,1) -> 29 | R2: =IF(E2=2,1,0) -> 0 | S2: =IF(E2=3,1,0) -> 0 | T2: =IF(C2=2,1,0) -> 0 | U2: =IF(C2=3,1,0) -> 1 | V2: =IF(C2=4,1,0) -> 0 | W2: =IF(L2=2012,1,0) -> 1 | X2: =CONVERT(F2,"C","F") -> 80.6
A3: 11326 | B3: 40738.042 | C3: 3 | D3: 0 | E3: 1 | F3: 24 | G3: 61 | H3: 16.9979 | I3: 4 | J3: 21 | K3: 25 | L3: =YEAR(B3) -> 2011 | M3: =MONTH(B3) -> 7 | N3: =WEEKDAY(B3,2) -> 4 | O3: =HOUR(B3) -> 1 | P3: =IF(N3>5,1,0) -> 0 | Q3: =WEEKNUM(B3,1) -> 29 | R3: =IF(E3=2,1,0) -> 0 | S3: =IF(E3=3,1,0) -> 0 | T3: =IF(C3=2,1,0) -> 0 | U3: =IF(C3=3,1,0) -> 1 | V3: =IF(C3=4,1,0) -> 0 | W3: =IF(L3=2012,1,0) -> 0 | X3: =CONVERT(F3,"C","F") -> 75.2
A4: 11327 | B4: 40582.208 | C4: 1 | D4: 0 | E4: 1 | F4: 4 | G4: 81 | H4: 22.0028 | I4: 0 | J4: 2 | K4: 2 | L4: =YEAR(B4) -> 2011 | M4: =MONTH(B4) -> 2 | N4: =WEEKDAY(B4,2) -> 2 | O4: =HOUR(B4) -> 5 | P4: =IF(N4>5,1,0) -> 0 | Q4: =WEEKNUM(B4,1) -> 7 | R4: =IF(E4=2,1,0) -> 0 | S4: =IF(E4=3,1,0) -> 0 | T4: =IF(C4=2,1,0) -> 0 | U4: =IF(C4=3,1,0) -> 0 | V4: =IF(C4=4,1,0) -> 0 | W4: =IF(L4=2012,1,0) -> 0 | X4: =CONVERT(F4,"C","F") -> 39.2
A5: 11328 | B5: 41056.333 | C5: 2 | D5: 0 | E5: 1 | F5: 23 | G5: 83 | H5: 12.998 | I5: 69 | J5: 82 | K5: 151 | L5: =YEAR(B5) -> 2012 | M5: =MONTH(B5) -> 5 | N5: =WEEKDAY(B5,2) -> 7 | O5: =HOUR(B5) -> 8 | P5: =IF(N5>5,1,0) -> 1 | Q5: =WEEKNUM(B5,1) -> 22 | R5: =IF(E5=2,1,0) -> 0 | S5: =IF(E5=3,1,0) -> 0 | T5: =IF(C5=2,1,0) -> 1 | U5: =IF(C5=3,1,0) -> 0 | V5: =IF(C5=4,1,0) -> 0 | W5: =IF(L5=2012,1,0) -> 1 | X5: =CONVERT(F5,"C","F") -> 73.4
A6: 11329 | B6: 40689.583 | C6: 2 | D6: 0 | E6: 1 | F6: 32 | G6: 52 | H6: 19.0012 | I6: 44 | J6: 145 | K6: 189 | L6: =YEAR(B6) -> 2011 | M6: =MONTH(B6) -> 5 | N6: =WEEKDAY(B6,2) -> 4 | O6: =HOUR(B6) -> 14 | P6: =IF(N6>5,1,0) -> 0 | Q6: =WEEKNUM(B6,1) -> 22 | R6: =IF(E6=2,1,0) -> 0 | S6: =IF(E6=3,1,0) -> 0 | T6: =IF(C6=2,1,0) -> 1 | U6: =IF(C6=3,1,0) -> 0 | V6: =IF(C6=4,1,0) -> 0 | W6: =IF(L6=2012,1,0) -> 0 | X6: =CONVERT(F6,"C","F") -> 89.6
A7: 11330 | B7: 41012.042 | C7: 2 | D7: 0 | E7: 1 | F7: 9 | G7: 46 | H7: 12.998 | I7: 2 | J7: 28 | K7: 30 | L7: =YEAR(B7) -> 2012 | M7: =MONTH(B7) -> 4 | N7: =WEEKDAY(B7,2) -> 5 | O7: =HOUR(B7) -> 1 | P7: =IF(N7>5,1,0) -> 0 | Q7: =WEEKNUM(B7,1) -> 15 | R7: =IF(E7=2,1,0) -> 0 | S7: =IF(E7=3,1,0) -> 0 | T7: =IF(C7=2,1,0) -> 1 | U7: =IF(C7=3,1,0) -> 0 | V7: =IF(C7=4,1,0) -> 0 | W7: =IF(L7=2012,1,0) -> 1 | X7: =CONVERT(F7,"C","F") -> 48.2
A8: 11331 | B8: 41111.958 | C8: 3 | D8: 0 | E8: 2 | F8: 21 | G8: 88 | H8: 0 | I8: 32 | J8: 117 | K8: 149 | L8: =YEAR(B8) -> 2012 | M8: =MONTH(B8) -> 7 | N8: =WEEKDAY(B8,2) -> 6 | O8: =HOUR(B8) -> 23 | P8: =IF(N8>5,1,0) -> 1 | Q8: =WEEKNUM(B8,1) -> 29 | R8: =IF(E8=2,1,0) -> 1 | S8: =IF(E8=3,1,0) -> 0 | T8: =IF(C8=2,1,0) -> 0 | U8: =IF(C8=3,1,0) -> 1 | V8: =IF(C8=4,1,0) -> 0 | W8: =IF(L8=2012,1,0) -> 1 | X8: =CONVERT(F8,"C","F") -> 69.8
A9: 11332 | B9: 40574.208 | C9: 1 | D9: 0 | E9: 1 | F9: 0 | G9: 64 | H9: 19.0012 | I9: 0 | J9: 8 | K9: 8 | L9: =YEAR(B9) -> 2011 | M9: =MONTH(B9) -> 1 | N9: =WEEKDAY(B9,2) -> 1 | O9: =HOUR(B9) -> 5 | P9: =IF(N9>5,1,0) -> 0 | Q9: =WEEKNUM(B9,1) -> 6 | R9: =IF(E9=2,1,0) -> 0 | S9: =IF(E9=3,1,0) -> 0 | T9: =IF(C9=2,1,0) -> 0 | U9: =IF(C9=3,1,0) -> 0 | V9: =IF(C9=4,1,0) -> 0 | W9: =IF(L9=2012,1,0) -> 0 | X9: =CONVERT(F9,"C","F") -> 32
A10: 11333 | B10: 40964.917 | C10: 1 | D10: 0 | E10: 1 | F10: 3 | G10: 38 | H10: 31.0009 | I10: 4 | J10: 78 | K10: 82 | L10: =YEAR(B10) -> 2012 | M10: =MONTH(B10) -> 2 | N10: =WEEKDAY(B10,2) -> 6 | O10: =HOUR(B10) -> 22 | P10: =IF(N10>5,1,0) -> 1 | Q10: =WEEKNUM(B10,1) -> 8 | R10: =IF(E10=2,1,0) -> 0 | S10: =IF(E10=3,1,0) -> 0 | T10: =IF(C10=2,1,0) -> 0 | U10: =IF(C10=3,1,0) -> 0 | V10: =IF(C10=4,1,0) -> 0 | W10: =IF(L10=2012,1,0) -> 1 | X10: =CONVERT(F10,"C","F") -> 37.4
A11: 11334 | B11: 41267.625 | C11: 1 | D11: 0 | E11: 3 | F11: 3 | G11: 87 | H11: 15.0013 | I11: 6 | J11: 27 | K11: 33 | L11: =YEAR(B11) -> 2012 | M11: =MONTH(B11) -> 12 | N11: =WEEKDAY(B11,2) -> 1 | O11: =HOUR(B11) -> 15 | P11: =IF(N11>5,1,0) -> 0 | Q11: =WEEKNUM(B11,1) -> 52 | R11: =IF(E11=2,1,0) -> 0 | S11: =IF(E11=3,1,0) -> 1 | T11: =IF(C11=2,1,0) -> 0 | U11: =IF(C11=3,1,0) -> 0 | V11: =IF(C11=4,1,0) -> 0 | W11: =IF(L11=2012,1,0) -> 1 | X11: =CONVERT(F11,"C","F") -> 37.4
A12: 11335 | B12: 41198.833 | C12: 4 | D12: 0 | E12: 1 | F12: 14 | G12: 55 | H12: 0 | I12: 35 | J12: 397 | K12: 432 | L12: =YEAR(B12) -> 2012 | M12: =MONTH(B12) -> 10 | N12: =WEEKDAY(B12,2) -> 2 | O12: =HOUR(B12) -> 20 | P12: =IF(N12>5,1,0) -> 0 | Q12: =WEEKNUM(B12,1) -> 42 | R12: =IF(E12=2,1,0) -> 0 | S12: =IF(E12=3,1,0) -> 0 | T12: =IF(C12=2,1,0) -> 0 | U12: =IF(C12=3,1,0) -> 0 | V12: =IF(C12=4,1,0) -> 1 | W12: =IF(L12=2012,1,0) -> 1 | X12: =CONVERT(F12,"C","F") -> 57.2
A13: 11336 | B13: 40567.958 | C13: 1 | D13: 0 | E13: 2 | F13: -1 | G13: 64 | H13: 16.9979 | I13: 3 | J13: 21 | K13: 24 | L13: =YEAR(B13) -> 2011 | M13: =MONTH(B13) -> 1 | N13: =WEEKDAY(B13,2) -> 1 | O13: =HOUR(B13) -> 23 | P13: =IF(N13>5,1,0) -> 0 | Q13: =WEEKNUM(B13,1) -> 5 | R13: =IF(E13=2,1,0) -> 1 | S13: =IF(E13=3,1,0) -> 0 | T13: =IF(C13=2,1,0) -> 0 | U13: =IF(C13=3,1,0) -> 0 | V13: =IF(C13=4,1,0) -> 0 | W13: =IF(L13=2012,1,0) -> 0 | X13: =CONVERT(F13,"C","F") -> 30.2
... A2335: 13664 | B2335: 41143.833 | C2335: 3 | D2335: 0 | E2335: 1 | F2335: 23 | G2335: 73 | H2335: 12.998 | I2335: 59 | J2335: 332 | K2335: 391 | L2335: =YEAR(B2335) -> 2012 | M2335: =MONTH(B2335) -> 8 | N2335: =WEEKDAY(B2335,2) -> 3 | O2335: =HOUR(B2335) -> 20 | P2335: =IF(N2335>5,1,0) -> 0 | Q2335: =WEEKNUM(B2335,1) -> 34 | R2335: =IF(E2335=2,1,0) -> 0 | S2335: =IF(E2335=3,1,0) -> 0 | T2335: =IF(C2335=2,1,0) -> 0 | U2335: =IF(C2335=3,1,0) -> 1 | V2335: =IF(C2335=4,1,0) -> 0 | W2335: =IF(L2335=2012,1,0) -> 1 | X2335: =CONVERT(F2335,"C","F") -> 73.4

Sheet P 2 Q1
A1: a) All | B1: avg | C1: 192.42759 | D1: Average of all_users | E1: Count of all_users2 | F1: StdDev of all_users3
B2: z-score | C2: 1.96 | D2: 192.42759 | E2: 2334 | F2: 183.87249
B3: st. dev | C3: 183.87249
B4: N | C4: 2334
B6: LB: | C6: =C1-C2*C3/SQRT(C4) -> 184.96787
B7: UP: | C7: =C1+C2*C3/SQRT(C4) -> 199.88731
A9: b) Casual | B9: avg | C9: 35.556127 | E9: Average of casual | F9: Count of casual2 | G9: StdDev of casual3
B10: z-score | C10: 1.96 | E10: 35.556127 | F10: 2334 | G10: 50.158395
B11: st. dev | C11: 50.158395
B12: N | C12: 2334
B14: LB: | C14: =C9-C10*C11/SQRT(C12) -> 33.521198
B15: UP: | C15: =C9+C10*C11/SQRT(C12) -> 37.591056
A17: c) Registered | B17: avg | C17: 156.87147 | E17: Average of registered | F17: Count of registered2 | G17: StdDev of registered3
B18: z-score | C18: 2.58 | E18: 156.87147 | F18: 2334 | G18: 154.55122
B19: st. dev | C19: 154.55122
B20: n | C20: 2334
B22: LB: | C22: =C17-C18*C19/SQRT(C20) -> 148.6179
B23: UP: | C23: =C17+C18*C19/SQRT(C20) -> 165.12503

Sheet P2 Q2
A1: all_users | B1: Weekend | E1: Weekend | F1: Weekday | H1: Row Labels | I1: Average of all_users | J1: Count of all_users2 | K1: StdDev of all_users3
A2: 312 | B2: 1 | D2: a) All | H2: Weekday | I2: 196.28149 | J2: 1691 | K2: 186.40307
A3: 25 | B3: 0 | D3: Mean | E3: 182.29238 | F3: 196.28149 | H3: Weekend | I3: 182.29238 | J3: 643 | K3: 176.78566
A4: 2 | B4: 0 | D4: st. dev | E4: 176.78566 | F4: 186.40307 | H4: Grand Total | I4: 192.42759 | J4: 2334 | K4: 183.87249
A5: 151 | B5: 1 | D5: sample size | E5: 1691 | F5: 643
A6: 189 | B6: 1
A7: 30 | B7: 0 | D7: b) casual | H7: Row Labels | I7: Average of casual | J7: Count of casual2 | K7: StdDev of casual3
A8: 149 | B8: 1 | D8: mean | E8: 59.70451 | F8: 26.373743 | H8: Weekday | I8: 26.373743 | J8: 1691 | K8: 31.27999
A9: 8 | B9: 0 | D9: st. dev | E9: 75.899711 | F9: 31.27999 | H9: Weekend | I9: 59.70451 | J9: 643 | K9: 75.899711
A10: 82 | B10: 1 | D10: sample size | E10: 1691 | F10: 643 | H10: Grand Total | I10: 35.556127 | J10: 2334 | K10: 50.158395
A11: 33 | B11: 1
A12: 432 | B12: 1 | D12: c) registered | H12: Row Labels | I12: Average of registered | J12: Count of registered2 | K12: StdDev of registered3
A13: 24 | B13: 1 | D13: mean | E13: 122.58787 | F13: 169.90775 | H13: Weekday | I13: 169.90775 | J13: 1691 | K13: 167.39773
A14: 505 | B14: 1 | D14: st. dev | E14: 106.82262 | F14: 167.39773 | H14: Weekend | I14: 122.58787 | J14: 643 | K14: 106.82262
A15: 193 | B15: 1 | D15: sample size | E15: 1691 | F15: 643 | H15: Grand Total | I15: 156.87147 | J15: 2334 | K15: 154.55122
A16: 110 | B16: 1
A17: 115 | B17: 1 | D17: d) All
A18: 36 | B18: 0 | D18: difference in mean | E18: =E3-F3 -> -13.989111 | H18: casual
A19: 797 | B19: 1 | D19: z-score | E19: 1.96 | H19: . | I19: Weekend | J19: Weekday
A20: 3 | B20: 0 | D20: st. dev squared over n 1 | E20: =F20/E5 -> 18.482064 | F20: =E4*E4 -> 31253.17 | H20: Mean | I20: 59.7 | J20: 26.37
A21: 404 | B21: 1 | D21: st. dev squared over n 2 | E21: =F21/F5 -> 54.037487 | F21: =F4*F4 -> 34746.104 | H21: Standard Deviation | I21: 75.9 | J21: 31.28
A22: 12 | B22: 0 | E22: =SQRT(E20+E21) -> 8.5158412 | H22: Sample Size | I22: 1691 | J22: 643
A23: 102 | B23: 1 | D23: LB: | E23: =E18-E19*E22 -> -30.680159
A24: 82 | B24: 1 | D24: UB: | E24: =E18+E19*E22 -> 2.7019379 | I24: Weekend | J24: Weekday
A25: 108 | B25: 1 | D25: Reject or fail to reject? | E25: fail to reject | H25: Mean | I25: 122.59 | J25: 169.91 | K25: registered
A26: 303 | B26: 1 | H26: Standard Deviation | I26: 106.82 | J26: 167.4
A27: 3 | B27: 0 | D27: e) Casual | H27: Sample Size | I27: 1691 | J27: 643
A28: 76 | B28: 1 | D28: difference in mean | E28: =E8-F8 -> 33.330767
A29: 222 | B29: 1 | D29: z-score | E29: 1.96 | H29: . | I29: Weekend | J29: Weekday
A30: 215 | B30: 1 | D30: st. dev squared over n 1 | E30: =F30/E10 -> 3.4067215 | F30: =E9*E9 -> 5760.7661 | H30: Mean | I30: 182.29 | J30: 196.28
A31: 225 | B31: 1 | D31: st. dev squared over n 2 | E31: =F31/F15 -> 1.5216761 | F31: =F9*F9 -> 978.43775 | H31: Standard Deviation | I31: 176.79 | J31: 186.4 | K31: all
A32: 11 | B32: 0 | E32: =SQRT(E30+E31) -> 2.2199995 | H32: Sample Size | I32: 1691 | J32: 643
A33: 90 | B33: 1 | D33: LB: | E33: =E28-E29*E32 -> 28.979568
A34: 462 | B34: 1 | D34: UP: | E34: =E28+E29*E32 -> 37.681966
A35: 436 | B35: 1 | D35: Reject or fail to reject? | E35: reject
A36: 302 | B36: 1
A37: 11 | B37: 0 | D37: f) Registered
A38: 98 | B38: 1 | D38: difference in mean | E38: =E13-F13 -> -47.319878
A39: 838 | B39: 1 | D39: z-score | E39: 1.96
A40: 83 | B40: 1 | D40: st. dev squared over n 1 | E40: =F40/E15 -> 6.7481202 | F40: =E14*E14 -> 11411.071
...

Sheet P2 Q 3
A1: all_users | B1: Temp (F) | D1: SUMMARY OUTPUT
A2: 312 | B2: 80.6
A3: 25 | B3: 75.2 | D3: Regression Statistics
A4: 2 | B4: 39.2 | D4: Multiple R | E4: 0.396797
A5: 151 | B5: 73.4 | D5: R Square | E5: 0.15744786
A6: 189 | B6: 89.6 | D6: Adjusted R Square | E6: 0.15708656
A7: 30 | B7: 48.2 | D7: Standard Error | E7: 168.81392
A8: 149 | B8: 69.8 | D8: Observations | E8: 2334
A9: 8 | B9: 32
A10: 82 | B10: 37.4 | E10: Coefficients | F10: Standard Error | G10: t Stat | H10: P-value | I10: Lower 95% | J10: Upper 95%
A11: 33 | B11: 37.4 | D11: Intercept | E11: -66.438426 | F11: 12.883459 | G11: -5.1568778 | H11: 2.7224132e-07 | I11: -91.702655 | J11: -41.174197
A12: 432 | B12: 57.2 | D12: Temp (F) | E12: 4.2936094 | F12: 0.20567821 | G12: 20.875374 | H12: 7.3168607e-89 | I12: 3.8902782 | J12: 4.6969407
A13: 24 | B13: 30.2
A14: 505 | B14: 98.6 | D14: a) | E14: 4.2936094
A15: 193 | B15: 73.4 | D15: b) | E15: 0.15744786
A16: 110 | B16: 64.4 | D16: c) | E16: =SQRT(E15) -> 0.396797
A17: 115 | B17: 41
A18: 36 | B18: 42.8
A19: 797 | B19: 62.6
A20: 3 | B20: 41
A21: 404 | B21: 71.6
A22: 12 | B22: 69.8
A23: 102 | B23: 44.6
A24: 82 | B24: 35.6
A25: 108 | B25: 57.2
A26: 303 | B26: 78.8
A27: 3 | B27: 24.8
A28: 76 | B28: 35.6
... A2335: 391 | B2335: 73.4

Sheet P2 Q4
A1: all_users | B1: Temp (F) | C1: Weekend | E1: SUMMARY OUTPUT | O1: casual | P1: Temp (F) | Q1: Weekend | S1: SUMMARY OUTPUT | AA1: registered | AB1: Temp (F) | AC1: Weekend | AE1: SUMMARY OUTPUT
A2: 312 | B2: 80.6 | C2: 1 | O2: 109 | P2: 80.6 | Q2: 1 | AA2: 203 | AB2: 80.6 | AC2: 1
A3: 25 | B3: 75.2 | C3: 0 | D3: =SUM(C2:C2335) -> 1763 | E3: Regression Statistics | O3: 4 | P3: 75.2 | Q3: 0 | S3: Regression Statistics | AA3: 21 | AB3: 75.2 | AC3: 0 | AE3: Regression Statistics
A4: 2 | B4: 39.2 | C4: 0 | E4: Multiple R | F4: 0.62150498 | O4: 0 | P4: 39.2 | Q4: 0 | S4: Multiple R | T4: 0.54681314 | AA4: 2 | AB4: 39.2 | AC4: 0 | AE4: Multiple R | AF4: 0.57149611
A5: 151 | B5: 73.4 | C5: 1 | E5: R Square | F5: 0.38626844 | O5: 69 | P5: 73.4 | Q5: 1 | S5: R Square | T5: 0.29900461 | AA5: 82 | AB5: 73.4 | AC5: 1 | AE5: R Square | AF5: 0.3266078
A6: 189 | B6: 89.6 | C6: 1 | E6: Adjusted R Square | F6: 0.38574186 | O6: 44 | P6: 89.6 | Q6: 1 | S6: Adjusted R Square | T6: 0.29840315 | AA6: 145 | AB6: 89.6 | AC6: 1 | AE6: Adjusted R Square | AF6: 0.32603003
A7: 30 | B7: 48.2 | C7: 0 | E7: Standard Error | F7: 144.10937 | O7: 2 | P7: 48.2 | Q7: 0 | S7: Standard Error | T7: 42.013363 | AA7: 28 | AB7: 48.2 | AC7: 0 | AE7: Standard Error | AF7: 126.87987
A8: 149 | B8: 69.8 | C8: 1 | E8: Observations | F8: 2334 | O8: 32 | P8: 69.8 | Q8: 1 | S8: Observations | T8: 2334 | AA8: 117 | AB8: 69.8 | AC8: 1 | AE8: Observations | AF8: 2334
A9: 8 | B9: 32 | C9: 0 | O9: 0 | P9: 32 | Q9: 0 | AA9: 8 | AB9: 32 | AC9: 0
A10: 82 | B10: 37.4 | C10: 1 | O10: 4 | P10: 37.4 | Q10: 1 | T10: Coefficients | U10: Standard Error | V10: t Stat | W10: P-value | X10: Lower 95% | Y10: Upper 95% | AA10: 78 | AB10: 37.4 | AC10: 1 | AF10: Coefficients | AG10: Standard Error | AH10: t Stat | AI10: P-value | AJ10: Lower 95% | AK10: Upper 95% | AL10: Lower 99.0% | AM10: Upper 99.0%
A11: 33 | B11: 37.4 | C11: 1 | F11: Coefficients | G11: Standard Error | H11: t Stat | I11: P-value | J11: Lower 95% | K11: Upper 95% | L11: Lower 90.0% | M11: Upper 90.0% | O11: 6 | P11: 37.4 | Q11: 1 | S11: Intercept | T11: -66.264267 | U11: 3.4217893 | V11: -19.365385 | W11: 1.3652079e-77 | X11: -72.974335 | Y11: -59.554199 | AA11: 27 | AB11: 37.4 | AC11: 1 | AE11: Intercept | AF11: -121.00759 | AG11: 10.333764 | AH11: -11.709924 | AI11: 8.1245445e-31 | AJ11: -141.27191 | AK11: -100.74326 | AL11: -147.64741 | AM11: -94.367762
A12: 432 | B12: 57.2 | C12: 1 | E12: Intercept | F12: -187.27185 | G12: 11.737025 | H12: -15.955649 | I12: 1.7925064e-54 | J12: -210.28795 | K12: -164.25576 | L12: -206.58522 | M12: -167.95849 | O12: 35 | P12: 57.2 | Q12: 1 | S12: Temp (F) | T12: 1.2413168 | U12: 0.051502176 | V12: 24.10222 | W12: 8.6558943e-115 | X12: 1.1403219 | Y12: 1.3423116 | AA12: 397 | AB12: 57.2 | AC12: 1 | AE12: Temp (F) | AF12: 2.4778569 | AG12: 0.15553597 | AH12: 15.931086 | AI12: 2.5551168e-54 | AJ12: 2.1728537 | AK12: 2.7828602 | AL12: 2.0768945 | AM12: 2.8788194
A13: 24 | B13: 30.2 | C13: 1 | E13: Temp (F) | F13: 3.7191737 | G13: 0.1766568 | H13: 21.053103 | I13: 3.1828209e-90 | J13: 3.3727529 | K13: 4.0655946 | L13: 3.4284836 | M13: 4.0098638 | O13: 3 | P13: 30.2 | Q13: 1 | S13: Weekend | T13: 35.718487 | U13: 2.0354094 | V13: 17.548552 | W13: 7.5054945e-65 | X13: 31.727085 | Y13: 39.709889 | AA13: 21 | AB13: 30.2 | AC13: 1 | AE13: Weekend | AF13: 170.10077 | AG13: 6.1469127 | AH13: 27.672554 | AI13: 5.4583475e-146 | AJ13: 158.04679 | AK13: 182.15476 | AL13: 154.2544 | AM13: 185.94714
A14: 505 | B14: 98.6 | C14: 1 | E14: Weekend | F14: 205.81926 | G14: 6.9816256 | H14: 29.480134 | I14: 1.2779346e-162 | J14: 192.12842 | K14: 219.5101 | L14: 194.33094 | M14: 217.30758 | O14: 79 | P14: 98.6 | Q14: 1 | AA14: 426 | AB14: 98.6 | AC14: 1
A15: 193 | B15: 73.4 | C15: 1 | O15: 20 | P15: 73.4 | Q15: 1 | S15: c) | T15: 35.718487 | AA15: 173 | AB15: 73.4 | AC15: 1 | AE15: e) | AF15: 170.10077
A16: 110 | B16: 64.4 | C16: 1 | E16: a) | F16: 205.81926 | O16: 5 | P16: 64.4 | Q16: 1 | S16: d) | T16: Is the weekend variable statstically significant? | AA16: 105 | AB16: 64.4 | AC16: 1 | AE16: f) | AF16: Is the weekend variable statstically significant?
A17: 115 | B17: 41 | C17: 1 | E17: b) | F17: Is the weekend variable statstically significant? | O17: 4 | P17: 41 | Q17: 1 | T17: yes | AA17: 111 | AB17: 41 | AC17: 1 | AF17: yes
A18: 36 | B18: 42.8 | C18: 0 | F18: yes | O18: 2 | P18: 42.8 | Q18: 0 | AA18: 34 | AB18: 42.8 | AC18: 0
A19: 797 | B19: 62.6 | C19: 1 | O19: 39 | P19: 62.6 | Q19: 1 | AA19: 758 | AB19: 62.6 | AC19: 1
A20: 3 | B20: 41 | C20: 0 | O20: 1 | P20: 41 | Q20: 0 | AA20: 2 | AB20: 41 | AC20: 0
A21: 404 | B21: 71.6 | C21: 1 | O21: 20 | P21: 71.6 | Q21: 1 | AA21: 384 | AB21: 71.6 | AC21: 1
A22: 12 | B22: 69.8 | C22: 0 | O22: 3 | P22: 69.8 | Q22: 0 | AA22: 9 | AB22: 69.8 | AC22: 0
A23: 102 | B23: 44.6 | C23: 1 | O23: 11 | P23: 44.6 | Q23: 1 | AA23: 91 | AB23: 44.6 | AC23: 1
A24: 82 | B24: 35.6 | C24: 1 | O24: 5 | P24: 35.6 | Q24: 1 | AA24: 77 | AB24: 35.6 | AC24: 1
A25: 108 | B25: 57.2 | C25: 1 | O25: 9 | P25: 57.2 | Q25: 1 | AA25: 99 | AB25: 57.2 | AC25: 1
A26: 303 | B26: 78.8 | C26: 1 | O26: 16 | P26: 78.8 | Q26: 1 | AA26: 287 | AB26: 78.8 | AC26: 1
A27: 3 | B27: 24.8 | C27: 0 | O27: 0 | P27: 24.8 | Q27: 0 | AA27: 3 | AB27: 24.8 | AC27: 0
A28: 76 | B28: 35.6 | C28: 1 | O28: 10 | P28: 35.6 | Q28: 1 | AA28: 66 | AB28: 35.6 | AC28: 1
A29: 222 | B29: 87.8 | C29: 1 | O29: 66 | P29: 87.8 | Q29: 1 | AA29: 156 | AB29: 87.8 | AC29: 1
A30: 215 | B30: 84.2 | C30: 1 | O30: 73 | P30: 84.2 | Q30: 1 | AA30: 142 | AB30: 84.2 | AC30: 1
... A2335: 391 | B2335: 73.4 | C2335: 1 | O2335: 59 | P2335: 73.4 | Q2335: 1 | AA2335: 332 | AB2335: 73.4 | AC2335: 1

Sheet P2 Q5
A1: all_users | B1: Temp (F) | C1: humidity | D1: windspeed | E1: Spring | F1: Summer | G1: Fall | H1: Weekend | I1: Year 2012 | J1: Mist | K1: Percipitation | L1: temp | M1: SUMMARY OUTPUT
A2: 312 | B2: 80.6 | C2: 84 | D2: 15.0013 | E2: 0 | F2: 1 | G2: 0 | H2: 1 | I2: 1 | J2: 0 | K2: 0 | L2: 27
A3: 25 | B3: 75.2 | C3: 61 | D3: 16.9979 | E3: 0 | F3: 1 | G3: 0 | H3: 0 | I3: 0 | J3: 0 | K3: 0 | L3: 24 | M3: Regression Statistics
A4: 2 | B4: 39.2 | C4: 81 | D4: 22.0028 | E4: 0 | F4: 0 | G4: 0 | H4: 0 | I4: 0 | J4: 0 | K4: 0 | L4: 4 | M4: Multiple R | N4: 0.70646899
A5: 151 | B5: 73.4 | C5: 83 | D5: 12.998 | E5: 1 | F5: 0 | G5: 0 | H5: 1 | I5: 1 | J5: 0 | K5: 0 | L5: 23 | M5: R Square | N5: 0.49909843
A6: 189 | B6: 89.6 | C6: 52 | D6: 19.0012 | E6: 1 | F6: 0 | G6: 0 | H6: 1 | I6: 0 | J6: 0 | K6: 0 | L6: 32 | M6: Adjusted R Square | N6: 0.49694216
A7: 30 | B7: 48.2 | C7: 46 | D7: 12.998 | E7: 1 | F7: 0 | G7: 0 | H7: 0 | I7: 1 | J7: 0 | K7: 0 | L7: 9 | M7: Standard Error | N7: 130.41445
A8: 149 | B8: 69.8 | C8: 88 | D8: 0 | E8: 0 | F8: 1 | G8: 0 | H8: 1 | I8: 1 | J8: 1 | K8: 0 | L8: 21 | M8: Observations | N8: 2334
A9: 8 | B9: 32 | C9: 64 | D9: 19.0012 | E9: 0 | F9: 0 | G9: 0 | H9: 0 | I9: 0 | J9: 0 | K9: 0 | L9: 0
A10: 82 | B10: 37.4 | C10: 38 | D10: 31.0009 | E10: 0 | F10: 0 | G10: 0 | H10: 1 | I10: 1 | J10: 0 | K10: 0 | L10: 3 | M10: ANOVA
A11: 33 | B11: 37.4 | C11: 87 | D11: 15.0013 | E11: 0 | F11: 0 | G11: 0 | H11: 1 | I11: 1 | J11: 0 | K11: 1 | L11: 3 | N11: df | O11: SS | P11: MS | Q11: F | R11: Significance F
A12: 432 | B12: 57.2 | C12: 55 | D12: 0 | E12: 0 | F12: 0 | G12: 1 | H12: 1 | I12: 1 | J12: 0 | K12: 0 | L12: 14 | M12: Regression | N12: 10 | O12: 39367196 | P12: 3936719.6 | Q12: 231.46377 | R12: 0
A13: 24 | B13: 30.2 | C13: 64 | D13: 16.9979 | E13: 0 | F13: 0 | G13: 0 | H13: 1 | I13: 0 | J13: 1 | K13: 0 | L13: -1 | M13: Residual | N13: 2323 | O13: 39509421 | P13: 17007.93
A14: 505 | B14: 98.6 | C14: 35 | D14: 15.0013 | E14: 1 | F14: 0 | G14: 0 | H14: 1 | I14: 0 | J14: 0 | K14: 0 | L14: 37 | M14: Total | N14: 2333 | O14: 78876617
A15: 193 | B15: 73.4 | C15: 89 | D15: 12.998 | E15: 0 | F15: 0 | G15: 1 | H15: 1 | I15: 0 | J15: 0 | K15: 1 | L15: 23
A16: 110 | B16: 64.4 | C16: 88 | D16: 19.0012 | E16: 1 | F16: 0 | G16: 0 | H16: 1 | I16: 1 | J16: 0 | K16: 1 | L16: 18 | N16: Coefficients | O16: Standard Error | P16: t Stat | Q16: P-value | R16: Lower 95% | S16: Upper 95% | T16: Lower 99.0% | U16: Upper 99.0%
A17: 115 | B17: 41 | C17: 56 | D17: 12.998 | E17: 0 | F17: 0 | G17: 1 | H17: 1 | I17: 1 | J17: 0 | K17: 0 | L17: 5 | M17: Intercept | N17: -110.32924 | O17: 18.727716 | P17: -5.8912277 | Q17: 4.3904317e-09 | R17: -147.05402 | S17: -73.604455 | T17: -158.60831 | U17: -62.050172
A18: 36 | B18: 42.8 | C18: 65 | D18: 6.0032 | E18: 0 | F18: 0 | G18: 1 | H18: 0 | I18: 1 | J18: 1 | K18: 0 | L18: 6 | M18: Temp (F) | N18: 3.7008709 | O18: 0.25743686 | P18: 14.375839 | Q18: 5.8777406e-45 | R18: 3.1960409 | S18: 4.2057009 | T18: 3.0372122 | U18: 4.3645296
A19: 797 | B19: 62.6 | C19: 59 | D19: 15.0013 | E19: 0 | F19: 1 | G19: 0 | H19: 1 | I19: 1 | J19: 0 | K19: 0 | L19: 17 | M19: humidity | N19: -1.8228999 | O19: 0.17229727 | P19: -10.579969 | Q19: 1.3955749e-25 | R19: -2.1607724 | S19: -1.4850274 | T19: -2.2670732 | U19: -1.3787266
A20: 3 | B20: 41 | C20: 41 | D20: 46.0022 | E20: 0 | F20: 0 | G20: 0 | H20: 0 | I20: 0 | J20: 0 | K20: 0 | L20: 5 | M20: windspeed | N20: -0.27141007 | O20: 0.35973217 | P20: -0.75447818 | Q20: 0.45063862 | R20: -0.97683972 | S20: 0.43401957 | T20: -1.1987807 | U20: 0.65596054
A21: 404 | B21: 71.6 | C21: 57 | D21: 16.9979 | E21: 0 | F21: 1 | G21: 0 | H21: 1 | I21: 0 | J21: 0 | K21: 0 | L21: 22 | M21: Spring | N21: 27.941221 | O21: 9.5510508 | P21: 2.9254604 | Q21: 0.0034728174 | R21: 9.2117466 | S21: 46.670695 | T21: 3.3191142 | U21: 52.563327
A22: 12 | B22: 69.8 | C22: 64 | D22: 0 | E22: 0 | F22: 1 | G22: 0 | H22: 0 | I22: 0 | J22: 0 | K22: 0 | L22: 21 | M22: Summer | N22: 2.1017442 | O22: 12.36043 | P22: 0.17003811 | Q22: 0.86499497 | R22: -22.136883 | S22: 26.340372 | T22: -29.762795 | U22: 33.966284
A23: 102 | B23: 44.6 | C23: 49 | D23: 31.0009 | E23: 0 | F23: 0 | G23: 0 | H23: 1 | I23: 0 | J23: 0 | K23: 0 | L23: 7 | M23: Fall | N23: 60.422624 | O23: 8.4525056 | P23: 7.1484867 | Q23: 1.1699533e-12 | R23: 43.847381 | S23: 76.997867 | T23: 38.632509 | U23: 82.212739
A24: 82 | B24: 35.6 | C24: 35 | D24: 23.9994 | E24: 0 | F24: 0 | G24: 0 | H24: 1 | I24: 0 | J24: 0 | K24: 0 | L24: 2 | M24: Weekend | N24: 182.17487 | O24: 6.7673441 | P24: 26.919699 | Q24: 3.6944505e-139 | R24: 168.9042 | S24: 195.44553 | T24: 164.72901 | U24: 199.62072
A25: 108 | B25: 57.2 | C25: 67 | D25: 26.0027 | E25: 0 | F25: 0 | G25: 1 | H25: 1 | I25: 0 | J25: 1 | K25: 0 | L25: 14 | M25: Year 2012 | N25: 82.478524 | O25: 5.4606754 | P25: 15.104088 | Q25: 3.0677739e-49 | R25: 71.770217 | S25: 93.18683 | T25: 68.40119 | U25: 96.555858
A26: 303 | B26: 78.8 | C26: 58 | D26: 6.0032 | E26: 0 | F26: 1 | G26: 0 | H26: 1 | I26: 0 | J26: 0 | K26: 0 | L26: 26 | M26: Mist | N26: -2.7437063 | O26: 6.6344417 | P26: -0.41355496 | Q26: 0.67923824 | R26: -15.753752 | S26: 10.266339 | T26: -19.846948 | U26: 14.359535
A27: 3 | B27: 24.8 | C27: 49 | D27: 26.0027 | E27: 0 | F27: 0 | G27: 0 | H27: 0 | I27: 1 | J27: 0 | K27: 0 | L27: -4 | M27: Percipitation | N27: -39.433879 | O27: 10.821233 | P27: -3.6441209 | Q27: 0.00027419065 | R27: -60.654162 | S27: -18.213597 | T27: -67.330448 | U27: -11.537311
A28: 76 | B28: 35.6 | C28: 27 | D28: 39.0007 | E28: 0 | F28: 0 | G28: 0 | H28: 1 | I28: 0 | J28: 0 | K28: 0 | L28: 2
A29: 222 | B29: 87.8 | C29: 49 | D29: 7.0015 | E29: 0 | F29: 1 | G29: 0 | H29: 1 | I29: 0 | J29: 0 | K29: 0 | L29: 31 | M29: a) | N29: -2.7437063
A30: 215 | B30: 84.2 | C30: 52 | D30: 12.998 | E30: 1 | F30: 0 | G30: 0 | H30: 1 | I30: 0 | J30: 0 | K30: 0 | L30: 29 | M30: b) | N30: no
A31: 225 | B31: 80.6 | C31: 26 | D31: 23.9994 | E31: 1 | F31: 0 | G31: 0 | H31: 1 | I31: 0 | J31: 0 | K31: 0 | L31: 27 | M31: c) | N31: yes
A32: 11 | B32: 69.8 | C32: 40 | D32: 16.9979 | E32: 0 | F32: 1 | G32: 0 | H32: 0 | I32: 1 | J32: 0 | K32: 0 | L32: 21 | M32: d) | N32: =N22 -> 2.1017442 | O32: supposed to subrtact summer - 0
A33: 90 | B33: 39.2 | C33: 48 | D33: 26.0027 | E33: 0 | F33: 0 | G33: 0 | H33: 1 | I33: 1 | J33: 0 | K33: 0 | L33: 4 | M33: e) | N33: 3.7008709
A34: 462 | B34: 78.8 | C34: 45 | D34: 0 | E34: 1 | F34: 0 | G34: 0 | H34: 1 | I34: 0 | J34: 0 | K34: 0 | L34: 26 | M34: f) | N34: =N27 -> -39.433879 | O34: 0 - percipitation
A35: 436 | B35: 87.8 | C35: 46 | D35: 0 | E35: 0 | F35: 1 | G35: 0 | H35: 1 | I35: 0 | J35: 0 | K35: 0 | L35: 31 | M35: g) | N35: =N17+N22+N25+(N18*70)+(N20*5)+(N19*60) -> 122.58095
A36: 302 | B36: 68 | C36: 64 | D36: 12.998 | E36: 1 | F36: 0 | G36: 0 | H36: 1 | I36: 0 | J36: 0 | K36: 0 | L36: 20 | M36: h) | N36: 0.49909843 | R36: make another regression for just I use temp in celcius
A37: 11 | B37: 55.4 | C37: 54 | D37: 16.9979 | E37: 0 | F37: 0 | G37: 1 | H37: 0 | I37: 1 | J37: 1 | K37: 0 | L37: 13 | M37: i) | N37: 6.6615676
A38: 98 | B38: 48.2 | C38: 23 | D38: 0 | E38: 0 | F38: 0 | G38: 0 | H38: 1 | I38: 0 | J38: 1 | K38: 0 | L38: 9
A39: 838 | B39: 60.8 | C39: 42 | D39: 11.0014 | E39: 0 | F39: 0 | G39: 1 | H39: 1 | I39: 1 | J39: 0 | K39: 0 | L39: 16
A40: 83 | B40: 33.8 | C40: 69 | D40: 8.9981 | E40: 0 | F40: 0 | G40: 0 | H40: 1 | I40: 0 | J40: 0 | K40: 0 | L40: 1
...

Sheet P2 Q6
A1: a) | B1: 0.83696558 | D1: Row Labels | E1: Average of all_users | F1: Average of Temp (F) | H1: SUMMARY OUTPUT
A2: b) | B2: 0.70051137 | D2: 1 | E2: 150.74074 | F2: 44.066667
D3: 2 | E3: 92.875 | F3: 40.415 | H3: Regression Statistics
D4: 3 | E4: 94.446809 | F4: 33.608511 | H4: Multiple R | I4: 0.83696558
D5: 4 | E5: 127.40909 | F5: 41.45 | H5: R Square | I5: 0.70051137
D6: 5 | E6: 102.95918 | F6: 38.942857 | H6: Adjusted R Square | I6: 0.69463905
D7: 6 | E7: 115.12821 | F7: 39.707692 | H7: Standard Error | I7: 8.4675686
D8: 7 | E8: 116.77083 | F8: 38.45 | H8: Observations | I8: 53
D9: 8 | E9: 112.57143 | F9: 46.914286
D10: 9 | E10: 146.05714 | F10: 46.811429 | I10: Coefficients | J10: Standard Error | K10: t Stat | L10: P-value | M10: Lower 95% | N10: Upper 95%
D11: 10 | E11: 124.08108 | F11: 44.648649 | H11: Intercept | I11: 13.895018 | J11: 4.4046682 | K11: 3.1546118 | L11: 0.0026944906 | M11: 5.0522779 | N11: 22.737759
D12: 11 | E12: 164.95918 | F12: 52.865306 | H12: Average of all_users | I12: 0.24243605 | J12: 0.02219702 | K12: 10.922009 | L12: 5.8557029e-15 | M12: 0.19787367 | N12: 0.28699842
D13: 12 | E13: 188.95238 | F13: 58.914286
D14: 13 | E14: 159.79592 | F14: 49.669388 | H14: Average of all_users | I14: Average of Temp (F)
D15: 14 | E15: 189.875 | F15: 50.3375 | H15: 150.74074 | I15: 44.066667
D16: 15 | E16: 177.79245 | F16: 53.973585 | H16: 92.875 | I16: 40.415
D17: 16 | E17: 188.07692 | F17: 62.288462 | H17: 94.446809 | I17: 33.608511
D18: 17 | E18: 219.60417 | F18: 58.2125 | H18: 127.40909 | I18: 41.45
D19: 18 | E19: 237.38095 | F19: 66.585714 | H19: 102.95918 | I19: 38.942857
D20: 19 | E20: 253.6 | F20: 64.31 | H20: 115.12821 | I20: 39.707692
D21: 20 | E21: 202.08929 | F21: 65.846429 | H21: 116.77083 | I21: 38.45
D22: 21 | E22: 228.03704 | F22: 69.766667 | H22: 112.57143 | I22: 46.914286
D23: 22 | E23: 263.16 | F23: 77.792 | H23: 146.05714 | I23: 46.811429
D24: 23 | E24: 261.06 | F24: 76.064 | H24: 124.08108 | I24: 44.648649
D25: 24 | E25: 214.27083 | F25: 77.6 | H25: 164.95918 | I25: 52.865306
D26: 25 | E26: 224.88372 | F26: 76.916279 | H26: 188.95238 | I26: 58.914286
... D54: 53 | E54: 80.962963 | F54: 42.866667 | H54: 217.87234 | I54: 68.842553
D55: Grand Total | E55: 192.42759 | F55: 60.291003 | H55: 227.98182 | I55: 56.970909
H56: 255 | I56: 64.348571
H57: 223.57778 | I57: 61.92
H58: 163.68421 | I58: 50.047368
H59: 182.97778 | I59: 47.2
H60: 192.69388 | I60: 48.310204
H61: 161.68085 | I61: 49.195745
H62: 192.01887 | I62: 47.316981
H63: 196.425 | I63: 49.595
H64: 148.22917 | I64: 46.175
H65: 161.97368 | I65: 45.784211
H66: 106.4 | I66: 43.304
H67: 80.962963 | I67: 42.866667

Sheet not sure
A1: SUMMARY OUTPUT
A3: Regression Statistics
A4: Multiple R | B4: 0.83696558
A5: R Square | B5: 0.70051137
A6: Adjusted R Square | B6: 0.69463905
A7: Standard Error | B7: 8.4675686
A8: Observations | B8: 53
A10: ANOVA
B11: df | C11: SS | D11: MS | E11: F | F11: Significance F
A12: Regression | B12: 1 | C12: 8553.0791 | D12: 8553.0791 | E12: 119.29027 | F12: 5.8557029e-15
A13: Residual | B13: 51 | C13: 3656.6857 | D13: 71.699719
A14: Total | B14: 52 | C14: 12209.765
B16: Coefficients | C16: Standard Error | D16: t Stat | E16: P-value | F16: Lower 95% | G16: Upper 95% | H16: Lower 95.0% | I16: Upper 95.0%
A17: Intercept | B17: 13.895018 | C17: 4.4046682 | D17: 3.1546118 | E17: 0.0026944906 | F17: 5.0522779 | G17: 22.737759 | H17: 5.0522779 | I17: 22.737759
A18: Average of all_users | B18: 0.24243605 | C18: 0.02219702 | D18: 10.922009 | E18: 5.8557029e-15 | F18: 0.19787367 | G18: 0.28699842 | H18: 0.19787367 | I18: 0.28699842

Sheet not suree
A1: SUMMARY OUTPUT
A3: Regression Statistics
A4: Multiple R | B4: 0.83696558
A5: R Square | B5: 0.70051137
A6: Adjusted R Square | B6: 0.69463905
A7: Standard Error | B7: 29.232714
A8: Observations | B8: 53
A10: ANOVA
B11: df | C11: SS | D11: MS | E11: F | F11: Significance F
A12: Regression | B12: 1 | C12: 101939.69 | D12: 101939.69 | E12: 119.29027 | F12: 5.8557029e-15
A13: Residual | B13: 51 | C13: 43582.129 | D13: 854.55154
A14: Total | B14: 52 | C14: 145521.82
B16: Coefficients | C16: Standard Error | D16: t Stat | E16: P-value | F16: Lower 95% | G16: Upper 95% | H16: Lower 95.0% | I16: Upper 95.0%
A17: Intercept | B17: 17.17043 | C17: 16.449034 | D17: 1.0438564 | E17: 0.30147464 | F17: -15.852385 | G17: 50.193244 | H17: -15.852385 | I17: 50.193244
A18: Average of Temp (F) | B18: 2.8894687 | C18: 0.2645547 | D18: 10.922009 | E18: 5.8557029e-15 | F18: 2.358353 | G18: 3.4205845 | H18: 2.358353 | I18: 3.4205845

Sheet P2 Q7
A1: all_users | B1: Temp (F) | C1: Spring | D1: Summer | E1: Fall | F1: Year 2012 | G1: Weekend | H1: Mist | I1: Percipitation | J1: windspeed | K1: SUMMARY OUTPUT | N1: SUMMARY OUTPUT | P1: all_users | Q1: Temp (F) | R1: Spring | S1: Summer | T1: Fall | U1: Year 2012 | V1: Weekend | W1: Mist | X1: Percipitation | Y1: humidity | AA1: all_users | AB1: Temp (F) | AC1: Spring | AD1: Summer | AE1: Fall | AF1: Year 2012 | AG1: Weekend | AH1: Mist | AI1: Percipitation | AK1: SUMMARY OUTPUT
A2: 312 | B2: 80.6 | C2: 0 | D2: 1 | E2: 0 | F2: 1 | G2: 1 | H2: 0 | I2: 0 | J2: 15.0013 | K2: WINDSPEED | N2: HUMIDITY | P2: 312 | Q2: 80.6 | R2: 0 | S2: 1 | T2: 0 | U2: 1 | V2: 1 | W2: 0 | X2: 0 | Y2: 84 | AA2: 312 | AB2: 80.6 | AC2: 0 | AD2: 1 | AE2: 0 | AF2: 1 | AG2: 1 | AH2: 0 | AI2: 0
A3: 25 | B3: 75.2 | C3: 0 | D3: 1 | E3: 0 | F3: 0 | G3: 0 | H3: 0 | I3: 0 | J3: 16.9979 | K3: Regression Statistics | N3: Regression Statistics | P3: 25 | Q3: 75.2 | R3: 0 | S3: 1 | T3: 0 | U3: 0 | V3: 0 | W3: 0 | X3: 0 | Y3: 61 | AA3: 25 | AB3: 75.2 | AC3: 0 | AD3: 1 | AE3: 0 | AF3: 0 | AG3: 0 | AH3: 0 | AI3: 0 | AK3: Regression Statistics
A4: 2 | B4: 39.2 | C4: 0 | D4: 0 | E4: 0 | F4: 0 | G4: 0 | H4: 0 | I4: 0 | J4: 22.0028 | K4: Multiple R | L4: 0.52277704 | N4: Multiple R | O4: 0.58528491 | P4: 2 | Q4: 39.2 | R4: 0 | S4: 0 | T4: 0 | U4: 0 | V4: 0 | W4: 0 | X4: 0 | Y4: 81 | AA4: 2 | AB4: 39.2 | AC4: 0 | AD4: 0 | AE4: 0 | AF4: 0 | AG4: 0 | AH4: 0 | AI4: 0 | AK4: Multiple R | AL4: 0.51270396
A5: 151 | B5: 73.4 | C5: 1 | D5: 0 | E5: 0 | F5: 1 | G5: 1 | H5: 0 | I5: 0 | J5: 12.998 | K5: R Square | L5: 0.27329584 | N5: R Square | O5: 0.34255842 | P5: 151 | Q5: 73.4 | R5: 1 | S5: 0 | T5: 0 | U5: 1 | V5: 1 | W5: 0 | X5: 0 | Y5: 83 | AA5: 151 | AB5: 73.4 | AC5: 1 | AD5: 0 | AE5: 0 | AF5: 1 | AG5: 1 | AH5: 0 | AI5: 0 | AK5: R Square | AL5: 0.26286535
A6: 189 | B6: 89.6 | C6: 1 | D6: 0 | E6: 0 | F6: 0 | G6: 0 | H6: 0 | I6: 0 | J6: 19.0012 | K6: Adjusted R Square | L6: 0.27048158 | N6: Adjusted R Square | O6: 0.34001239 | P6: 189 | Q6: 89.6 | R6: 1 | S6: 0 | T6: 0 | U6: 0 | V6: 0 | W6: 0 | X6: 0 | Y6: 52 | AA6: 189 | AB6: 89.6 | AC6: 1 | AD6: 0 | AE6: 0 | AF6: 0 | AG6: 0 | AH6: 0 | AI6: 0 | AK6: Adjusted R Square | AL6: 0.26032897
A7: 30 | B7: 48.2 | C7: 1 | D7: 0 | E7: 0 | F7: 1 | G7: 0 | H7: 0 | I7: 0 | J7: 12.998 | K7: Standard Error | L7: 157.0489 | N7: Standard Error | O7: 149.37732 | P7: 30 | Q7: 48.2 | R7: 1 | S7: 0 | T7: 0 | U7: 1 | V7: 0 | W7: 0 | X7: 0 | Y7: 46 | AA7: 30 | AB7: 48.2 | AC7: 1 | AD7: 0 | AE7: 0 | AF7: 1 | AG7: 0 | AH7: 0 | AI7: 0 | AK7: Standard Error | AL7: 158.13794
A8: 149 | B8: 69.8 | C8: 0 | D8: 1 | E8: 0 | F8: 1 | G8: 1 | H8: 1 | I8: 0 | J8: 0 | K8: Observations | L8: 2334 | N8: Observations | O8: 2334 | P8: 149 | Q8: 69.8 | R8: 0 | S8: 1 | T8: 0 | U8: 1 | V8: 1 | W8: 1 | X8: 0 | Y8: 88 | AA8: 149 | AB8: 69.8 | AC8: 0 | AD8: 1 | AE8: 0 | AF8: 1 | AG8: 1 | AH8: 1 | AI8: 0 | AK8: Observations | AL8: 2334
A9: 8 | B9: 32 | C9: 0 | D9: 0 | E9: 0 | F9: 0 | G9: 0 | H9: 0 | I9: 0 | J9: 19.0012 | P9: 8 | Q9: 32 | R9: 0 | S9: 0 | T9: 0 | U9: 0 | V9: 0 | W9: 0 | X9: 0 | Y9: 64 | AA9: 8 | AB9: 32 | AC9: 0 | AD9: 0 | AE9: 0 | AF9: 0 | AG9: 0 | AH9: 0 | AI9: 0
A10: 82 | B10: 37.4 | C10: 0 | D10: 0 | E10: 0 | F10: 1 | G10: 1 | H10: 0 | I10: 0 | J10: 31.0009 | P10: 82 | Q10: 37.4 | R10: 0 | S10: 0 | T10: 0 | U10: 1 | V10: 1 | W10: 0 | X10: 0 | Y10: 38 | AA10: 82 | AB10: 37.4 | AC10: 0 | AD10: 0 | AE10: 0 | AF10: 1 | AG10: 1 | AH10: 0 | AI10: 0 | AK10: ANOVA
A11: 33 | B11: 37.4 | C11: 0 | D11: 0 | E11: 0 | F11: 1 | G11: 0 | H11: 0 | I11: 1 | J11: 15.0013 | L11: a) | M11: 0.26286535 | P11: 33 | Q11: 37.4 | R11: 0 | S11: 0 | T11: 0 | U11: 1 | V11: 0 | W11: 0 | X11: 1 | Y11: 87 | AA11: 33 | AB11: 37.4 | AC11: 0 | AD11: 0 | AE11: 0 | AF11: 1 | AG11: 0 | AH11: 0 | AI11: 1 | AL11: df | AM11: SS | AN11: MS | AO11: F | AP11: Significance F
A12: 432 | B12: 57.2 | C12: 0 | D12: 0 | E12: 1 | F12: 1 | G12: 0 | H12: 0 | I12: 0 | J12: 0 | L12: b) | M12: humidity is more useful | P12: 432 | Q12: 57.2 | R12: 0 | S12: 0 | T12: 1 | U12: 1 | V12: 0 | W12: 0 | X12: 0 | Y12: 55 | AA12: 432 | AB12: 57.2 | AC12: 0 | AD12: 0 | AE12: 1 | AF12: 1 | AG12: 0 | AH12: 0 | AI12: 0 | AK12: Regression | AL12: 8 | AM12: 20733929 | AN12: 2591741.2 | AO12: 103.63811 | AP12: 5.079244e-148
A13: 24 | B13: 30.2 | C13: 0 | D13: 0 | E13: 0 | F13: 0 | G13: 0 | H13: 1 | I13: 0 | J13: 16.9979 | P13: 24 | Q13: 30.2 | R13: 0 | S13: 0 | T13: 0 | U13: 0 | V13: 0 | W13: 1 | X13: 0 | Y13: 64 | AA13: 24 | AB13: 30.2 | AC13: 0 | AD13: 0 | AE13: 0 | AF13: 0 | AG13: 0 | AH13: 1 | AI13: 0 | AK13: Residual | AL13: 2325 | AM13: 58142688 | AN13: 25007.608
A14: 505 | B14: 98.6 | C14: 1 | D14: 0 | E14: 0 | F14: 0 | G14: 0 | H14: 0 | I14: 0 | J14: 15.0013 | P14: 505 | Q14: 98.6 | R14: 1 | S14: 0 | T14: 0 | U14: 0 | V14: 0 | W14: 0 | X14: 0 | Y14: 35 | AA14: 505 | AB14: 98.6 | AC14: 1 | AD14: 0 | AE14: 0 | AF14: 0 | AG14: 0 | AH14: 0 | AI14: 0 | AK14: Total | AL14: 2333 | AM14: 78876617
A15: 193 | B15: 73.4 | C15: 0 | D15: 0 | E15: 1 | F15: 0 | G15: 0 | H15: 0 | I15: 1 | J15: 12.998 | P15: 193 | Q15: 73.4 | R15: 0 | S15: 0 | T15: 1 | U15: 0 | V15: 0 | W15: 0 | X15: 1 | Y15: 89 | AA15: 193 | AB15: 73.4 | AC15: 0 | AD15: 0 | AE15: 1 | AF15: 0 | AG15: 0 | AH15: 0 | AI15: 1
A16: 110 | B16: 64.4 | C16: 1 | D16: 0 | E16: 0 | F16: 1 | G16: 0 | H16: 0 | I16: 1 | J16: 19.0012 | P16: 110 | Q16: 64.4 | R16: 1 | S16: 0 | T16: 0 | U16: 1 | V16: 0 | W16: 0 | X16: 1 | Y16: 88 | AA16: 110 | AB16: 64.4 | AC16: 1 | AD16: 0 | AE16: 0 | AF16: 1 | AG16: 0 | AH16: 0 | AI16: 1 | AL16: Coefficients | AM16: Standard Error | AN16: t Stat | AO16: P-value | AP16: Lower 95% | AQ16: Upper 95% | AR16: Lower 95.0% | AS16: Upper 95.0%
A17: 115 | B17: 41 | C17: 0 | D17: 0 | E17: 1 | F17: 1 | G17: 0 | H17: 0 | I17: 0 | J17: 12.998 | P17: 115 | Q17: 41 | R17: 0 | S17: 0 | T17: 1 | U17: 1 | V17: 0 | W17: 0 | X17: 0 | Y17: 56 | AA17: 115 | AB17: 41 | AC17: 0 | AD17: 0 | AE17: 1 | AF17: 1 | AG17: 0 | AH17: 0 | AI17: 0 | AK17: Intercept | AL17: -164.98866 | AM17: 15.569796 | AN17: -10.596713 | AO17: 1.1753694e-25 | AP17: -195.52079 | AQ17: -134.45653 | AR17: -195.52079 | AS17: -134.45653
A18: 36 | B18: 42.8 | C18: 0 | D18: 0 | E18: 1 | F18: 1 | G18: 0 | H18: 1 | I18: 0 | J18: 6.0032 | P18: 36 | Q18: 42.8 | R18: 0 | S18: 0 | T18: 1 | U18: 1 | V18: 0 | W18: 1 | X18: 0 | Y18: 65 | AA18: 36 | AB18: 42.8 | AC18: 0 | AD18: 0 | AE18: 1 | AF18: 1 | AG18: 0 | AH18: 1 | AI18: 0 | AK18: Temp (F) | AL18: 5.8334769 | AM18: 0.30306744 | AN18: 19.248115 | AO18: 9.9722869e-77 | AP18: 5.2391663 | AQ18: 6.4277876 | AR18: 5.2391663 | AS18: 6.4277876
A19: 797 | B19: 62.6 | C19: 0 | D19: 1 | E19: 0 | F19: 1 | G19: 0 | H19: 0 | I19: 0 | J19: 15.0013 | P19: 797 | Q19: 62.6 | R19: 0 | S19: 1 | T19: 0 | U19: 1 | V19: 0 | W19: 0 | X19: 0 | Y19: 59 | AA19: 797 | AB19: 62.6 | AC19: 0 | AD19: 1 | AE19: 0 | AF19: 1 | AG19: 0 | AH19: 0 | AI19: 0 | AK19: Spring | AL19: -25.256093 | AM19: 11.355671 | AN19: -2.2240953 | AO19: 0.026237743 | AP19: -47.524391 | AQ19: -2.9877956 | AR19: -47.524391 | AS19: -2.9877956
A20: 3 | B20: 41 | C20: 0 | D20: 0 | E20: 0 | F20: 0 | G20: 0 | H20: 0 | I20: 0 | J20: 46.0022 | P20: 3 | Q20: 41 | R20: 0 | S20: 0 | T20: 0 | U20: 0 | V20: 0 | W20: 0 | X20: 0 | Y20: 41 | AA20: 3 | AB20: 41 | AC20: 0 | AD20: 0 | AE20: 0 | AF20: 0 | AG20: 0 | AH20: 0 | AI20: 0 | AK20: Summer | AL20: -100.50792 | AM20: 14.368677 | AN20: -6.9949318 | AO20: 3.4563489e-12 | AP20: -128.68468 | AQ20: -72.33116 | AR20: -128.68468 | AS20: -72.33116
A21: 404 | B21: 71.6 | C21: 0 | D21: 1 | E21: 0 | F21: 0 | G21: 0 | H21: 0 | I21: 0 | J21: 16.9979 | P21: 404 | Q21: 71.6 | R21: 0 | S21: 1 | T21: 0 | U21: 0 | V21: 0 | W21: 0 | X21: 0 | Y21: 57 | AA21: 404 | AB21: 71.6 | AC21: 0 | AD21: 1 | AE21: 0 | AF21: 0 | AG21: 0 | AH21: 0 | AI21: 0 | AK21: Fall | AL21: 25.288401 | AM21: 9.9274211 | AN21: 2.5473284 | AO21: 0.010919013 | AP21: 5.820879 | AQ21: 44.755924 | AR21: 5.820879 | AS21: 44.755924
A22: 12 | B22: 69.8 | C22: 0 | D22: 1 | E22: 0 | F22: 0 | G22: 1 | H22: 0 | I22: 0 | J22: 0 | P22: 12 | Q22: 69.8 | R22: 0 | S22: 1 | T22: 0 | U22: 0 | V22: 1 | W22: 0 | X22: 0 | Y22: 64 | AA22: 12 | AB22: 69.8 | AC22: 0 | AD22: 1 | AE22: 0 | AF22: 0 | AG22: 1 | AH22: 0 | AI22: 0 | AK22: Year 2012 | AL22: 84.844443 | AM22: 6.5853501 | AN22: 12.883817 | AO22: 9.7263728e-37 | AP22: 71.930671 | AQ22: 97.758215 | AR22: 71.930671 | AS22: 97.758215
A23: 102 | B23: 44.6 | C23: 0 | D23: 0 | E23: 0 | F23: 0 | G23: 0 | H23: 0 | I23: 0 | J23: 31.0009 | P23: 102 | Q23: 44.6 | R23: 0 | S23: 0 | T23: 0 | U23: 0 | V23: 0 | W23: 0 | X23: 0 | Y23: 49 | AA23: 102 | AB23: 44.6 | AC23: 0 | AD23: 0 | AE23: 0 | AF23: 0 | AG23: 0 | AH23: 0 | AI23: 0 | AK23: Weekend | AL23: -0.23039695 | AM23: 7.3602366 | AN23: -0.031302928 | AO23: 0.97503064 | AP23: -14.663709 | AQ23: 14.202915 | AR23: -14.663709 | AS23: 14.202915
A24: 82 | B24: 35.6 | C24: 0 | D24: 0 | E24: 0 | F24: 0 | G24: 1 | H24: 0 | I24: 0 | J24: 23.9994 | P24: 82 | Q24: 35.6 | R24: 0 | S24: 0 | T24: 0 | U24: 0 | V24: 1 | W24: 0 | X24: 0 | Y24: 35 | AA24: 82 | AB24: 35.6 | AC24: 0 | AD24: 0 | AE24: 0 | AF24: 0 | AG24: 1 | AH24: 0 | AI24: 0 | AK24: Mist | AL24: -24.661119 | AM24: 7.6474812 | AN24: -3.2247374 | AO24: 0.0012783594 | AP24: -39.657713 | AQ24: -9.664524 | AR24: -39.657713 | AS24: -9.664524
A25: 108 | B25: 57.2 | C25: 0 | D25: 0 | E25: 1 | F25: 0 | G25: 0 | H25: 1 | I25: 0 | J25: 26.0027 | P25: 108 | Q25: 57.2 | R25: 0 | S25: 0 | T25: 1 | U25: 0 | V25: 0 | W25: 1 | X25: 0 | Y25: 67 | AA25: 108 | AB25: 57.2 | AC25: 0 | AD25: 0 | AE25: 1 | AF25: 0 | AG25: 0 | AH25: 1 | AI25: 0 | AK25: Percipitation | AL25: -71.689044 | AM25: 12.143423 | AN25: -5.9035283 | AO25: 4.0791563e-09 | AP25: -95.502113 | AQ25: -47.875975 | AR25: -95.502113 | AS25: -47.875975
A26: 303 | B26: 78.8 | C26: 0 | D26: 1 | E26: 0 | F26: 0 | G26: 0 | H26: 0 | I26: 0 | J26: 6.0032 | P26: 303 | Q26: 78.8 | R26: 0 | S26: 1 | T26: 0 | U26: 0 | V26: 0 | W26: 0 | X26: 0 | Y26: 58 | AA26: 303 | AB26: 78.8 | AC26: 0 | AD26: 1 | AE26: 0 | AF26: 0 | AG26: 0 | AH26: 0 | AI26: 0
A27: 3 | B27: 24.8 | C27: 0 | D27: 0 | E27: 0 | F27: 1 | G27: 1 | H27: 0 | I27: 0 | J27: 26.0027 | P27: 3 | Q27: 24.8 | R27: 0 | S27: 0 | T27: 0 | U27: 1 | V27: 1 | W27: 0 | X27: 0 | Y27: 49 | AA27: 3 | AB27: 24.8 | AC27: 0 | AD27: 0 | AE27: 0 | AF27: 1 | AG27: 1 | AH27: 0 | AI27: 0
A28: 76 | B28: 35.6 | C28: 0 | D28: 0 | E28: 0 | F28: 0 | G28: 0 | H28: 0 | I28: 0 | J28: 39.0007 | P28: 76 | Q28: 35.6 | R28: 0 | S28: 0 | T28: 0 | U28: 0 | V28: 0 | W28: 0 | X28: 0 | Y28: 27 | AA28: 76 | AB28: 35.6 | AC28: 0 | AD28: 0 | AE28: 0 | AF28: 0 | AG28: 0 | AH28: 0 | AI28: 0
A29: 222 | B29: 87.8 | C29: 0 | D29: 1 | E29: 0 | F29: 0 | G29: 0 | H29: 0 | I29: 0 | J29: 7.0015 | P29: 222 | Q29: 87.8 | R29: 0 | S29: 1 | T29: 0 | U29: 0 | V29: 0 | W29: 0 | X29: 0 | Y29: 49 | AA29: 222 | AB29: 87.8 | AC29: 0 | AD29: 1 | AE29: 0 | AF29: 0 | AG29: 0 | AH29: 0 | AI29: 0
A30: 215 | B30: 84.2 | C30: 1 | D30: 0 | E30: 0 | F30: 0 | G30: 0 | H30: 0 | I30: 0 | J30: 12.998 | P30: 215 | Q30: 84.2 | R30: 1 | S30: 0 | T30: 0 | U30: 0 | V30: 0 | W30: 0 | X30: 0 | Y30: 52 | AA30: 215 | AB30: 84.2 | AC30: 1 | AD30: 0 | AE30: 0 | AF30: 0 | AG30: 0 | AH30: 0 | AI30: 0
A31: 225 | B31: 80.6 | C31: 1 | D31: 0 | E31: 0 | F31: 0 | G31: 0 | H31: 0 | I31: 0 | J31: 23.9994 | P31: 225 | Q31: 80.6 | R31: 1 | S31: 0 | T31: 0 | U31: 0 | V31: 0 | W31: 0 | X31: 0 | Y31: 26 | AA31: 225 | AB31: 80.6 | AC31: 1 | AD31: 0 | AE31: 0 | AF31: 0 | AG31: 0 | AH31: 0 | AI31: 0
A32: 11 | B32: 69.8 | C32: 0 | D32: 1 | E32: 0 | F32: 1 | G32: 0 | H32: 0 | I32: 0 | J32: 16.9979 | P32: 11 | Q32: 69.8 | R32: 0 | S32: 1 | T32: 0 | U32: 1 | V32: 0 | W32: 0 | X32: 0 | Y32: 40 | AA32: 11 | AB32: 69.8 | AC32: 0 | AD32: 1 | AE32: 0 | AF32: 1 | AG32: 0 | AH32: 0 | AI32: 0
A33: 90 | B33: 39.2 | C33: 0 | D33: 0 | E33: 0 | F33: 1 | G33: 1 | H33: 0 | I33: 0 | J33: 26.0027 | P33: 90 | Q33: 39.2 | R33: 0 | S33: 0 | T33: 0 | U33: 1 | V33: 1 | W33: 0 | X33: 0 | Y33: 48 | AA33: 90 | AB33: 39.2 | AC33: 0 | AD33: 0 | AE33: 0 | AF33: 1 | AG33: 1 | AH33: 0 | AI33: 0
A34: 462 | B34: 78.8 | C34: 1 | D34: 0 | E34: 0 | F34: 0 | G34: 1 | H34: 0 | I34: 0 | J34: 0 | P34: 462 | Q34: 78.8 | R34: 1 | S34: 0 | T34: 0 | U34: 0 | V34: 1 | W34: 0 | X34: 0 | Y34: 45 | AA34: 462 | AB34: 78.8 | AC34: 1 | AD34: 0 | AE34: 0 | AF34: 0 | AG34: 1 | AH34: 0 | AI34: 0
A35: 436 | B35: 87.8 | C35: 0 | D35: 1 | E35: 0 | F35: 0 | G35: 0 | H35: 0 | I35: 0 | J35: 0 | P35: 436 | Q35: 87.8 | R35: 0 | S35: 1 | T35: 0 | U35: 0 | V35: 0 | W35: 0 | X35: 0 | Y35: 46 | AA35: 436 | AB35: 87.8 | AC35: 0 | AD35: 1 | AE35: 0 | AF35: 0 | AG35: 0 | AH35: 0 | AI35: 0
A36: 302 | B36: 68 | C36: 1 | D36: 0 | E36: 0 | F36: 0 | G36: 0 | H36: 0 | I36: 0 | J36: 12.998 | P36: 302 | Q36: 68 | R36: 1 | S36: 0 | T36: 0 | U36: 0 | V36: 0 | W36: 0 | X36: 0 | Y36: 64 | AA36: 302 | AB36: 68 | AC36: 1 | AD36: 0 | AE36: 0 | AF36: 0 | AG36: 0 | AH36: 0 | AI36: 0
A37: 11 | B37: 55.4 | C37: 0 | D37: 0 | E37: 1 | F37: 1 | G37: 1 | H37: 1 | I37: 0 | J37: 16.9979 | P37: 11 | Q37: 55.4 | R37: 0 | S37: 0 | T37: 1 | U37: 1 | V37: 1 | W37: 1 | X37: 0 | Y37: 54 | AA37: 11 | AB37: 55.4 | AC37: 0 | AD37: 0 | AE37: 1 | AF37: 1 | AG37: 1 | AH37: 1 | AI37: 0
... A2335: 391 | B2335: 73.4 | C2335: 0 | D2335: 1 | E2335: 0 | F2335: 1 | G2335: 0 | H2335: 0 | I2335: 0 | J2335: 12.998 | P2335: 391 | Q2335: 73.4 | R2335: 0 | S2335: 1 | T2335: 0 | U2335: 1 | V2335: 0 | W2335: 0 | X2335: 0 | Y2335: 73 | AA2335: 391 | AB2335: 73.4 | AC2335: 0 | AD2335: 1 | AE2335: 0 | AF2335: 1 | AG2335: 0 | AH2335: 0 | AI2335: 0

Sheet checkpoint
A1: a | B1: 11325 | C1: 13664
A2: b | B2: 2334
A3: c | B3: 240.14
A4: d | B4: 345
A5: e | B5: 102.2
A6: f | B6: 26.64
A7: g | B7: 149.98 | C7: 162.52 | H7: Average of registered | I7: StdDev of registered2 | J7: Count of registered3
H8: 156.87147 | I8: 154.55122 | J8: 2334
D9: x_bar | E9: 156.87147
D10: z | E10: 1.96
D11: s | E11: 154.55122
D12: n | E12: 2334 | F12: =SQRT(E12) -> 48.311489
D14: LB: | E14: =E9-E10*E11/F12 -> 150.60131
D15: UP: | E15: =E9+E10*E11/F12 -> 163.14162

Sheet P1 Q1
A1: a | B1: average | C1: =AVERAGE('Processed Data'!I2:I2335) -> 35.556127 | F1: Casual Users | G1: Registered Users
A2: b | B2: median | C2: =MEDIAN('Processed Data'!I2:I2335) -> 17 | E2: Average | F2: 35.56 | G2: 156.87
A3: c | B3: minimum | C3: =MIN('Processed Data'!I2:I2335) -> 0 | E3: Median | F3: 17 | G3: 115
A4: d | B4: maximum | C4: =MAX('Processed Data'!I2:I2335) -> 354 | E4: Maximum | F4: 354 | G4: 876
A5: e | B5: first quartile | C5: =_xlfn.QUARTILE.EXC('Processed Data'!I2:I2335,1) -> 4
A6: f | B6: third quartile | C6: =_xlfn.QUARTILE.EXC('Processed Data'!I2:I2335,3) -> 47
A7: g | B7: standard deviation | C7: =_xlfn.STDEV.S('Processed Data'!I2:I2335) -> 50.158395

Sheet P1 Q2
A1: a | B1: average | C1: =AVERAGE('Processed Data'!J2:J2335) -> 156.87147
A2: b | B2: median | C2: =MEDIAN('Processed Data'!J2:J2335) -> 115
A3: c | B3: minimum | C3: =MIN('Processed Data'!J2:J2335) -> 0 | E3: Registered | F3: Users
A4: d | B4: maximum | C4: =MAX('Processed Data'!J2:J2335) -> 876 | E4: Average | F4: 156.87
A5: e | B5: first quartile | C5: =_xlfn.QUARTILE.EXC('Processed Data'!J2:J2335,1) -> 36 | E5: Median | F5: 115
A6: f | B6: third quartile | C6: =_xlfn.QUARTILE.EXC('Processed Data'!J2:J2335,3) -> 225 | E6: Maximum | F6: 876
A7: g | B7: standard deviation | C7: =_xlfn.STDEV.S('Processed Data'!J2:J2335) -> 154.55122

Sheet P1 Q3
A1: a | B1: 82988 | C1: causal | E1: Row Labels | F1: Sum of casual | G1: Sum of registered | H1: Sum of all_users
A2: b | B2: 366138 | C2: registered | E2: 2011 | F2: 33160 | G2: 135243 | H2: 168403
A3: c | B3: =GETPIVOTDATA("Sum of casual",$E$1)/A11 -> 0.18477666 | E3: 2012 | F3: 49828 | G3: 230895 | H3: 280723
A4: d | B4: =GETPIVOTDATA("Sum of casual",$E$1,"Year",2011)/GETPIVOTDATA("Sum of all_users",$E$1,"Year",2011) -> 0.19690861 | E4: Grand Total | F4: 82988 | G4: 366138 | H4: 449126
B7: Casual | C7: Registered
B8: 82988 | C8: 366138
A11: =GETPIVOTDATA("Sum of casual",$E$1)+GETPIVOTDATA("Sum of registered",$E$1) -> 449126

Sheet P1 Q4
A1: a | B1: 216.64789 | D1: Row Labels | E1: Average of all_users | G1: spring | H1: summer | I1: fall | J1: winter
A2: b | B2: 49.133816 | D2: 0 | E2: 183.29676 | G2: 217 | H2: 230 | I2: 203
A3: c | B3: 174.247 | D3: 1 | E3: 216.64789
D4: Grand Total | E4: 192.42759
D7: Row Labels | E7: Average of casual
D8: 0 | E8: 31.340258
D9: 1 | E9: 49.133816
D10: Grand Total | E10: 35.556127
D13: Row Labels | E13: Average of registered
D14: 0 | E14: 151.08624
D15: 1 | E15: 174.247
D16: Grand Total | E16: 156.87147
D18: Row Labels | E18: Average of all_users
D19: 0 | E19: 188.98115
D20: 1 | E20: 202.77873
D21: Grand Total | E21: 192.42759

Sheet P1 Q5
A1: a | B1: 3111 | D1: Row Labels | E1: Sum of casual | F1: Sum of registered | G1: Sum of all_users
A2: b | B2: 14062 | D2: 2011 | E2: 33160 | F2: 135243 | G2: 168403 | K2: 2011 | L2: 2012
A3: c | B3: 31380 | D3: 1 | E3: 371 | F3: 4675 | G3: 5046 | J3: January | K3: 5046 | L3: 15710
A4: d | B4: =H4+H17 -> 21677 | D4: 2 | E4: 1038 | F4: 5078 | G4: 6116 | H4: 6116 | J4: February | K4: 6116 | L4: 15561
D5: 3 | E5: 1522 | F5: 5822 | G5: 7344 | J5: March | K5: 7344 | L5: 22631
D6: 4 | E6: 3492 | F6: 11510 | G6: 15002 | J6: April | K6: 15002 | L6: 28955
D7: 5 | E7: 5303 | F7: 17395 | G7: 22698 | J7: May | K7: 22698 | L7: 28713
D8: 6 | E8: 3766 | F8: 14730 | G8: 18496 | J8: June | K8: 18496 | L8: 23579
D9: 7 | E9: 4690 | F9: 12759 | G9: 17449 | J9: July | K9: 17449 | L9: 22570
D10: 8 | E10: 3111 | F10: 12436 | G10: 15547 | J10: August | K10: 15547 | L10: 31380
D11: 9 | E11: 3384 | F11: 12203 | G11: 15587 | J11: September | K11: 15587 | L11: 28844
D12: 10 | E12: 3078 | F12: 13864 | G12: 16942 | J12: October | K12: 16942 | L12: 25807
D13: 11 | E13: 2361 | F13: 14564 | G13: 16925 | J13: November | K13: 16925 | L13: 20975
D14: 12 | E14: 1044 | F14: 10207 | G14: 11251 | J14: December | K14: 11251 | L14: 15998
D15: 2012 | E15: 49828 | F15: 230895 | G15: 280723
D16: 1 | E16: 1327 | F16: 14383 | G16: 15710
D17: 2 | E17: 1499 | F17: 14062 | G17: 15561 | H17: 15561
D18: 3 | E18: 3815 | F18: 18816 | G18: 22631
D19: 4 | E19: 6676 | F19: 22279 | G19: 28955
D20: 5 | E20: 7110 | F20: 21603 | G20: 28713
D21: 6 | E21: 4612 | F21: 18967 | G21: 23579
D22: 7 | E22: 4400 | F22: 18170 | G22: 22570
D23: 8 | E23: 6426 | F23: 24954 | G23: 31380
D24: 9 | E24: 5607 | F24: 23237 | G24: 28844
D25: 10 | E25: 4066 | F25: 21741 | G25: 25807
D26: 11 | E26: 2622 | F26: 18353 | G26: 20975
D27: 12 | E27: 1668 | F27: 14330 | G27: 15998
D28: Grand Total | E28: 82988 | F28: 366138 | G28: 449126

Sheet P1 Q6
A1: a | B1: 185.57101 | D1: Row Labels | E1: Average of all_users | F1: Average of registered | G1: Average of casual
A2: b | B2: 27.788344 | D2: 1 | E2: 185.57101 | F2: 154.5913 | G2: 30.97971 | H2: Monday
A3: c | B3: 126.31871 | D3: 2 | E3: 224.7994 | F3: 199.06587 | G3: 25.733533 | H3: Tuesday
D4: 3 | E4: 198.39769 | F4: 175.24784 | G4: 23.149856 | H4: Wednesday
D5: 4 | E5: 193.67847 | F5: 169.42183 | G5: 24.256637 | H5: Thursday
D6: 5 | E6: 178.85276 | F6: 151.06442 | G6: 27.788344 | H6: Friday
D7: 6 | E7: 187.17544 | F7: 126.31871 | G7: 60.856725 | H7: Saturday
D8: 7 | E8: 176.74419 | F8: 118.34884 | G8: 58.395349 | H8: Sunday
D9: Grand Total | E9: 192.42759 | F9: 156.87147 | G9: 35.556127
B11: Casual | C11: Registered | D11: All Users
A12: Monday | B12: 30.97971 | C12: 154.5913 | D12: 185.57101
A13: Tuesday | B13: 25.733533 | C13: 199.06587 | D13: 224.7994
A14: Wednesday | B14: 23.149856 | C14: 175.24784 | D14: 198.39769
A15: Thursday | B15: 24.256637 | C15: 169.42183 | D15: 193.67847
A16: Friday | B16: 27.788344 | C16: 151.06442 | D16: 178.85276
A17: Saturday | B17: 60.856725 | C17: 126.31871 | D17: 187.17544
A18: Sunday | B18: 58.395349 | C18: 118.34884 | D18: 176.74419

Sheet P1 Q7
A1: a | B1: 241 | D1: Weekend | E1: 0 | J1: Row Labels | K1: Average of registered | L1: Average of casual
A2: b | B2: 166.48 | J2: Weekday | K2: 169.90775 | L2: 26.373743
A3: c | B3: 39.54 | D3: Row Labels | E3: Average of all_users | F3: Average of registered | G3: Average of casual | J3: Weekend | K3: 122.58787 | L3: 59.70451
A4: d | B4: 100.45 | D4: 0 | E4: 36.369231 | F4: 28.769231 | G4: 7.6 | J4: Grand Total | K4: 156.87147 | L4: 35.556127
A5: e | B5: 160.93 | D5: 1 | E5: 17.852459 | F5: 14.114754 | G5: 3.7377049 | O5: weekday
A6: f | B6: 278.54 | D6: 2 | E6: 8.7820513 | F6: 6.6410256 | G6: 2.1410256 | K6: Registered | L6: Casual | N6: registered | O6: 20.225919
D7: 3 | E7: 4.6461538 | F7: 3.9230769 | G7: 0.72307692 | J7: Weekday | K7: 169.90775 | L7: 26.373743 | N7: casual | O7: 4.4886165
D8: 4 | E8: 6.6140351 | F8: 5.3333333 | G8: 1.2807018 | J8: Weekend | K8: 122.58787 | L8: 59.70451
D9: 5 | E9: 26.128205 | F9: 24.512821 | G9: 1.6153846
D10: 6 | E10: 93.41791 | F10: 89.641791 | G10: 3.7761194
D11: 7 | E11: 270 | F11: 258.16438 | G11: 11.835616 | J11: Average of Registered | K11: Average of Casual
D12: 8 | E12: 475.06579 | F12: 451.02632 | G12: 24.039474 | J12: 28.769231 | K12: 7.6
D13: 9 | E13: 241 | F13: 216.07143 | G13: 24.928571 | J13: 14.114754 | K13: 3.7377049
D14: 10 | E14: 135.44444 | F14: 102.38272 | G14: 33.061728 | J14: 6.6410256 | K14: 2.1410256
D15: 11 | E15: 161.73529 | F15: 122.19118 | G15: 39.544118 | J15: 3.9230769 | K15: 0.72307692
D16: 12 | E16: 173.13793 | F16: 136.32759 | G16: 36.810345 | J16: 5.3333333 | K16: 1.2807018
D17: 13 | E17: 203.71667 | F17: 160.93333 | G17: 42.783333 | J17: 24.512821 | K17: 1.6153846
D18: 14 | E18: 204.31818 | F18: 150 | G18: 54.318182 | J18: 89.641791 | K18: 3.7761194
D19: 15 | E19: 188.7625 | F19: 146.25 | G19: 42.5125 | J19: 258.16438 | K19: 11.835616
D20: 16 | E20: 315.6 | F20: 263.72941 | G20: 51.870588 | J20: 451.02632 | K20: 24.039474
D21: 17 | E21: 540.71053 | F21: 478.81579 | G21: 61.894737 | J21: 216.07143 | K21: 24.928571
D22: 18 | E22: 486.98529 | F22: 438.02941 | G22: 48.955882 | J22: 102.38272 | K22: 33.061728
D23: 19 | E23: 323.65 | F23: 287.63333 | G23: 36.016667 | J23: 122.19118 | K23: 39.544118
... D27: 23 | E27: 78.893939 | F27: 66.424242 | G27: 12.469697 | J27: 146.25 | K27: 42.5125
B28: Weekend | C28: 1 | D28: Grand Total | E28: 196.28149 | F28: 169.90775 | G28: 26.373743 | J28: 263.72941 | K28: 51.870588
J29: 478.81579 | K29: 61.894737
B30: Row Labels | C30: Average of casual | D30: Average of registered | E30: Sum of all_users | J30: 438.02941 | K30: 48.955882
B31: 0 | C31: 20.357143 | D31: 79.464286 | E31: 2795 | J31: 287.63333 | K31: 36.016667
B32: 1 | C32: 11.037037 | D32: 52.222222 | E32: 1708 | J32: 225.22892 | K32: 32.746988
B33: 2 | C33: 9.8965517 | D33: 43.482759 | E33: 1548 | J33: 162.5 | K33: 25.068966
B34: 3 | C34: 5.40625 | D34: 20.0625 | E34: 815 | J34: 130.70513 | K34: 22.717949
B35: 4 | C35: 2.1538462 | D35: 5.6923077 | E35: 204 | J35: 66.424242 | K35: 12.469697
B36: 5 | C36: 1.76 | D36: 5.72 | E36: 187 | N36: Average of Registered | O36: Average of Casual
B37: 6 | C37: 4.75 | D37: 12.25 | E37: 272 | N37: 20.357143 | O37: 79.464286
B38: 7 | C38: 6.6153846 | D38: 35.269231 | E38: 1089 | N38: 11.037037 | O38: 52.222222
B39: 8 | C39: 20.846154 | D39: 82.115385 | E39: 2677 | N39: 9.8965517 | O39: 43.482759
B40: 9 | C40: 44.068966 | D40: 122.41379 | E40: 4828 | N40: 5.40625 | O40: 20.0625
B41: 10 | C41: 74.653846 | D41: 170.84615 | E41: 6383 | N41: 2.1538462 | O41: 5.6923077
B42: 11 | C42: 100.45 | D42: 191.3 | E42: 5835 | N42: 1.76 | O42: 5.72
B43: 12 | C43: 135.35484 | D43: 239.16129 | E43: 11610 | N43: 4.75 | O43: 12.25
...

Sheet P1 Q8
A1: a | B1: 344 | C1: casual | D1: registered | F1: bins
A2: b | B2: 702 | C2: 109 | D2: 203 | F2: 50
C3: 4 | D3: 21 | F3: 100 | L3: registered
C4: 0 | D4: 2 | F4: 150 | I4: registered | L4: 50 | M4: =J6/J15 -> 0.30077121
C5: 69 | D5: 82 | F5: 200 | I5: bins | J5: Frequency | L5: 100 | M5: =J7/J15 -> 0.15424165
C6: 44 | D6: 145 | F6: 250 | I6: 50 | J6: 702 | L6: 150 | M6: =J8/J15 -> 0.13667524
C7: 2 | D7: 28 | F7: 300 | I7: 100 | J7: 360 | L7: 200 | M7: =J9/J15 -> 0.11311054
C8: 32 | D8: 117 | F8: 350 | I8: 150 | J8: 319 | L8: 250 | M8: =J10/J15 -> 0.083976007
C9: 0 | D9: 8 | F9: 400 | I9: 200 | J9: 264 | L9: 300 | M9: =J11/J15 -> 0.059125964
C10: 4 | D10: 78 | I10: 250 | J10: 196 | L10: 350 | M10: =J12/J15 -> 0.040274207
C11: 6 | D11: 27 | I11: 300 | J11: 138 | L11: 400 | M11: =J13/J15 -> 0.032133676
C12: 35 | D12: 397 | I12: 350 | J12: 94 | L12: More | M12: =J14/J15 -> 0.079691517
C13: 3 | D13: 21 | F13: casual | I13: 400 | J13: 75
C14: 79 | D14: 426 | F14: bins | G14: Frequency | I14: More | J14: 186
C15: 20 | D15: 173 | F15: 50 | G15: 1797 | J15: 2334 | L15: =SUM(J6:J14) -> 2334
C16: 5 | D16: 105 | F16: 100 | G16: 344
C17: 4 | D17: 111 | F17: 150 | G17: 92
C18: 2 | D18: 34 | F18: 200 | G18: 48
C19: 39 | D19: 758 | F19: 250 | G19: 31
C20: 1 | D20: 2 | F20: 300 | G20: 16
C21: 20 | D21: 384 | F21: 350 | G21: 5
C22: 3 | D22: 9 | F22: 400 | G22: 1
C23: 11 | D23: 91 | F23: More | G23: 0
C24: 5 | D24: 77 | G24: 2334
C25: 9 | D25: 99 | F25: casual
C26: 16 | D26: 287 | F26: 50 | G26: =G15/G24 -> 0.76992288
C27: 0 | D27: 3 | F27: 100 | G27: =G16/G24 -> 0.14738646
C28: 10 | D28: 66 | F28: 150 | G28: =G17/G24 -> 0.039417309
C29: 66 | D29: 156 | F29: 200 | G29: =G18/G24 -> 0.020565553
C30: 73 | D30: 142 | F30: 250 | G30: =G19/G24 -> 0.013281919
C31: 28 | D31: 197 | F31: 300 | G31: =G20/G24 -> 0.0068551842
C32: 0 | D32: 11 | F32: 350 | G32: =G21/G24 -> 0.0021422451
C33: 13 | D33: 77 | F33: 400 | G33: =G22/G24 -> 0.00042844901
C34: 191 | D34: 271
C35: 240 | D35: 196
C36: 55 | D36: 247
C37: 5 | D37: 6
C38: 28 | D38: 70
C39: 71 | D39: 767
C40: 8 | D40: 75
...
